<?xml version="1.0" ?>
<!-- =================================================================================== -->
<!-- |    This document was autogenerated by xacro from src/cobot_description/urdf/main.xacro | -->
<!-- |    EDITING THIS FILE BY HAND IS NOT RECOMMENDED                                 | -->
<!-- =================================================================================== -->
<robot name="main">
  <link name="base_link">
    <inertial>
      <origin rpy="0.0 0.0 0.0" xyz="0.000696452473990524 -1.170323750862548e-10 0.030371653659111337"/>
      <mass value="6.621911264861204"/>
      <inertia ixx="0.00923937323696488" ixy="4.5979814145310376e-12" ixz="-2.1996132580219004e-05" iyy="0.009511010438696694" iyz="5.7989392972185086e-12" izz="0.014108201739142418"/>
    </inertial>
    <visual>
      <origin rpy="0.0 0.0 0.0" xyz="0.0 0.0 0.0"/>
      <geometry>
        <mesh filename="package://cobot_description/meshes/base-v1.stl" scale="0.001 0.001 0.001"/>
      </geometry>
    </visual>
    <collision>
      <origin rpy="0.0 0.0 0.0" xyz="0.0 0.0 0.0"/>
      <geometry>
        <mesh filename="package://cobot_description/meshes/base-v1.stl" scale="0.001 0.001 0.001"/>
      </geometry>
    </collision>
  </link>
  <link name="world"/>
  <joint name="base_joint" type="fixed">
    <origin rpy="0 0 0" xyz="0 0 0"/>
    <parent link="world"/>
    <child link="base_link"/>
  </joint>
  <gazebo reference="base_link">
    <material>Gazebo/White</material>
  </gazebo>
  <link name="part-1-link">
    <inertial>
      <origin rpy="0.0 -0.0 0.0" xyz="4.2600783800908005e-08 -0.004626848631395353 0.08705302776882812"/>
      <mass value="19.236789838028937"/>
      <inertia ixx="0.0650605674783421" ixy="-2.7738089948544564e-08" ixz="5.761162613379028e-09" iyy="0.06330931409180679" iyz="-7.617928665559943e-05" izz="0.04583430207124484"/>
    </inertial>
    <visual>
      <origin rpy="-2.0007731365775954e-15 1.5707963267948615 0" xyz="2.486899575160354e-16 5.217407854026423e-31 0.007000000000000002"/>
      <geometry>
        <mesh filename="package://cobot_description/meshes/part_1-v1.stl" scale="0.001 0.001 0.001"/>
      </geometry>
    </visual>
    <collision>
      <origin rpy="-2.0007731365775954e-15 1.5707963267948615 0" xyz="2.486899575160354e-16 5.217407854026423e-31 0.007000000000000002"/>
      <geometry>
        <mesh filename="package://cobot_description/meshes/part_1-v1.stl" scale="0.001 0.001 0.001"/>
      </geometry>
    </collision>
  </link>
  <joint name="part-1-joint" type="continuous">
    <origin rpy="0.0 -0.0 0.0" xyz="0.0 0.0 0.064"/>
    <parent link="base_link"/>
    <child link="part-1-link"/>
    <axis xyz="0.0 0.0 1.0"/>
  </joint>
  <gazebo reference="part-1-link">
    <material>Gazebo/SkyBlue</material>
  </gazebo>
  <link name="part-2-link">
    <inertial>
      <origin rpy="0.0 -9.865958957339894e-74 0.0" xyz="-6.446385462448829e-08 0.22299980820732856 0.08703678624211574"/>
      <mass value="55.527652767250565"/>
      <inertia ixx="2.1297738755873112" ixy="4.861709959453926e-07" ixz="-4.633156234161857e-08" iyy="0.147373948306055" iyz="-4.512210840523778e-07" izz="2.0913212409037367"/>
    </inertial>
    <visual>
      <origin rpy="-1.5707963267948968 1.570796326794874 0" xyz="3.0730973321624325e-15 5.329070518200751e-17 0.006999999999999949"/>
      <geometry>
        <mesh filename="package://cobot_description/meshes/part_2-v1.stl" scale="0.001 0.001 0.001"/>
      </geometry>
    </visual>
    <collision>
      <origin rpy="-1.5707963267948968 1.570796326794874 0" xyz="3.0730973321624325e-15 5.329070518200751e-17 0.006999999999999949"/>
      <geometry>
        <mesh filename="package://cobot_description/meshes/part_2-v1.stl" scale="0.001 0.001 0.001"/>
      </geometry>
    </collision>
  </link>
  <joint name="part-2-joint" type="continuous">
    <origin rpy="1.5707963267948966 6.310887241768095e-30 2.627434620609032e-46" xyz="0.0 -0.073 0.087"/>
    <parent link="part-1-link"/>
    <child link="part-2-link"/>
    <axis xyz="-2.627434620609032e-46 -3.9443045261049027e-31 1.0"/>
  </joint>
  <gazebo reference="part-2-link">
    <material>Gazebo/White</material>
  </gazebo>
  <link name="part-3-link">
    <inertial>
      <origin rpy="0.0 -0.0 0.0" xyz="0.08223933957765624 -0.04157100588820313 2.5299350090164364e-08"/>
      <mass value="15.694173292697611"/>
      <inertia ixx="0.01856384488278667" ixy="-0.0033503648953676635" ixz="1.489426454503982e-08" iyy="0.19681939777632707" iyz="2.198790124899759e-09" izz="0.19356660242428525"/>
    </inertial>
    <visual>
      <origin rpy="-1.5707963267948966 -4.1633363423443124e-16 -1.5707963267948966" xyz="-1.2079226507921704e-15 -0.007000000000000437 6.061817714453354e-15"/>
      <geometry>
        <mesh filename="package://cobot_description/meshes/part_3-v1.stl" scale="0.001 0.001 0.001"/>
      </geometry>
    </visual>
    <collision>
      <origin rpy="-1.5707963267948966 -4.1633363423443124e-16 -1.5707963267948966" xyz="-1.2079226507921704e-15 -0.007000000000000437 6.061817714453354e-15"/>
      <geometry>
        <mesh filename="package://cobot_description/meshes/part_3-v1.stl" scale="0.001 0.001 0.001"/>
      </geometry>
    </collision>
  </link>
  <joint name="part-3-joint" type="continuous">
    <origin rpy="1.5707963267948966 -3.9443045261049342e-31 1.5707963267948966" xyz="-2.81465570982857e-30 0.446 0.0"/>
    <parent link="part-2-link"/>
    <child link="part-3-link"/>
    <axis xyz="-3.1529215447308384e-45 -1.0 -3.155443620884051e-30"/>
  </joint>
  <gazebo reference="part-3-link">
    <material>Gazebo/SkyBlue</material>
  </gazebo>
  <link name="part-4-link">
    <inertial>
      <origin rpy="0.0 -0.0 0.0" xyz="-9.964764281805767e-09 0.0005092612480414572 0.043842704011179165"/>
      <mass value="7.044315932933864"/>
      <inertia ixx="0.0154961131603093" ixy="-6.173461578096984e-09" ixz="-1.3663136217143062e-09" iyy="0.007001845317182287" iyz="-1.6168831524859817e-05" izz="0.01516808354624834"/>
    </inertial>
    <visual>
      <origin rpy="1.5707963267949538 1.1102230246249783e-16 -1.570796326794892" xyz="3.810285420513545e-15 -0.07025000036135261 0.04599999999999852"/>
      <geometry>
        <mesh filename="package://cobot_description/meshes/part_4-v3.stl" scale="0.001 0.001 0.001"/>
      </geometry>
    </visual>
    <collision>
      <origin rpy="1.5707963267949538 1.1102230246249783e-16 -1.570796326794892" xyz="3.810285420513545e-15 -0.07025000036135261 0.04599999999999852"/>
      <geometry>
        <mesh filename="package://cobot_description/meshes/part_4-v3.stl" scale="0.001 0.001 0.001"/>
      </geometry>
    </collision>
  </link>
  <joint name="part-4-joint" type="continuous">
    <origin rpy="3.141592653589793 -1.5707963267948966 0" xyz="0.315 -0.039 -1.2582639587066229e-31"/>
    <parent link="part-3-link"/>
    <child link="part-4-link"/>
    <axis xyz="0.0 0.0 1.0"/>
  </joint>
  <gazebo reference="part-2-link">
    <material>Gazebo/White</material>
  </gazebo>
  <link name="part-5-link">
    <inertial>
      <origin rpy="0.0 -0.0 0.0" xyz="3.5971422768597e-05 0.044719085911557335 4.847035635505104e-08"/>
      <mass value="9.142141124336765"/>
      <inertia ixx="0.009192683309449917" ixy="6.814284787104441e-06" ixz="-1.4676667092811573e-08" iyy="0.029273595372682593" iyz="1.1225405233760152e-08" izz="0.029644876257586716"/>
    </inertial>
    <visual>
      <origin rpy="-4.3632632229506716e-14 2.4339905091430602e-14 -1.5707963267948966" xyz="0.09651106877055383 0.046000000361352544 7.405187574249764e-16"/>
      <geometry>
        <mesh filename="package://cobot_description/meshes/part_5-v1.stl" scale="0.001 0.001 0.001"/>
      </geometry>
    </visual>
    <collision>
      <origin rpy="-4.3632632229506716e-14 2.4339905091430602e-14 -1.5707963267948966" xyz="0.09651106877055383 0.046000000361352544 7.405187574249764e-16"/>
      <geometry>
        <mesh filename="package://cobot_description/meshes/part_5-v1.stl" scale="0.001 0.001 0.001"/>
      </geometry>
    </collision>
  </link>
  <joint name="part-5-joint" type="continuous">
    <origin rpy="3.141592653589793 -1.5707963267948966 0" xyz="-4.463174091164314e-34 -0.07475 0.045999999999999944"/>
    <parent link="part-4-link"/>
    <child link="part-5-link"/>
    <axis xyz="0.0 1.0 1.232595164407831e-32"/>
  </joint>
  <gazebo reference="part-3-link">
    <material>Gazebo/SkyBlue</material>
  </gazebo>
  <link name="part-6-link">
    <inertial>
      <origin rpy="0.0 6.029457624941381e-60 0.0" xyz="2.555898230010403e-09 -0.04375984625669176 0.0004891796217755307"/>
      <mass value="7.0552682041621555"/>
      <inertia ixx="0.015557066369455086" ixy="-2.1710702184334016e-09" ixz="-9.495811150880039e-09" iyy="0.015209168427560482" iyz="1.615008221045322e-05" izz="0.007036468228365678"/>
    </inertial>
    <visual>
      <origin rpy="3.1415926535896013 1.5707963267948881 0" xyz="8.935074902183196e-15 -0.04599999877055368 -0.070250001408159"/>
      <geometry>
        <mesh filename="package://cobot_description/meshes/part_6-v2.stl" scale="0.001 0.001 0.001"/>
      </geometry>
    </visual>
    <collision>
      <origin rpy="3.1415926535896013 1.5707963267948881 0" xyz="8.935074902183196e-15 -0.04599999877055368 -0.070250001408159"/>
      <geometry>
        <mesh filename="package://cobot_description/meshes/part_6-v2.stl" scale="0.001 0.001 0.001"/>
      </geometry>
    </collision>
  </link>
  <joint name="part-6-joint" type="continuous">
    <origin rpy="1.5707963267948966 -1.5707963267948966 0" xyz="0.09651106999999996 0.046 -8.587358456926641e-33"/>
    <parent link="part-5-link"/>
    <child link="part-6-link"/>
    <axis xyz="9.55405697163452e-31 -1.0 -6.310887241768095e-30"/>
  </joint>
  <gazebo reference="part-2-link">
    <material>Gazebo/White</material>
  </gazebo>
  <link name="gripper-base-link">
    <inertial>
      <origin rpy="0.0 0.0 0.0" xyz="-1.2294464113438154e-09 0.013528576288044327 8.953385102894012e-15"/>
      <mass value="0.7903113468473031"/>
      <inertia ixx="0.00035518576250788414" ixy="-5.551115123125783e-17" ixz="-2.0804537315342093e-17" iyy="0.000727459318582091" iyz="2.414692808250078e-19" izz="0.0004661570187922681"/>
    </inertial>
    <visual>
      <origin rpy="-1.5707963267948963 -1.5707963267947043 0" xyz="-1.2294464113438154e-09 1.4081590293812952e-09 8.930800543538389e-15"/>
      <geometry>
        <mesh filename="package://cobot_description/meshes/gripper_base-v1.stl" scale="0.001 0.001 0.001"/>
      </geometry>
    </visual>
    <collision>
      <origin rpy="-1.5707963267948963 -1.5707963267947043 0" xyz="-1.2294464113438154e-09 1.4081590293812952e-09 8.930800543538389e-15"/>
      <geometry>
        <mesh filename="package://cobot_description/meshes/gripper_base-v1.stl" scale="0.001 0.001 0.001"/>
      </geometry>
    </collision>
  </link>
  <joint name="gripper-base-joint" type="fixed">
    <origin rpy="-1.5707963267948966 6.310887241768095e-30 -1.5707963267948966" xyz="-1.3694132276640018e-32 -0.04600000000000009 -0.07075000000000001"/>
    <parent link="part-6-link"/>
    <child link="gripper-base-link"/>
  </joint>
  <gazebo reference="gripper-base-link">
    <material>Gazebo/White</material>
  </gazebo>
  <link name="finger-1-link">
    <inertial>
      <origin rpy="0.0 1.2446030555722283e-60 5.527147875260445e-76" xyz="-0.008443385199655925 0.03000000140815903 1.2294522377942484e-09"/>
      <mass value="0.2128834660023882"/>
      <inertia ixx="7.903229595107586e-05" ixy="2.168404344971024e-19" ixz="3.469446951953614e-18" iyy="1.9267709840176117e-05" iyz="1.3877787807814457e-17" izz="6.796549349066816e-05"/>
    </inertial>
    <visual>
      <origin rpy="-1.5707963267948963 -1.9230207024252956e-13 -2.813099754978189e-29" xyz="-0.04099999999999111 -0.01499999859184097 1.229445985018174e-09"/>
      <geometry>
        <mesh filename="package://cobot_description/meshes/finger_right-v1.stl" scale="0.001 0.001 0.001"/>
      </geometry>
    </visual>
    <collision>
      <origin rpy="-1.5707963267948963 -1.9230207024252956e-13 -2.813099754978189e-29" xyz="-0.04099999999999111 -0.01499999859184097 1.229445985018174e-09"/>
      <geometry>
        <mesh filename="package://cobot_description/meshes/finger_right-v1.stl" scale="0.001 0.001 0.001"/>
      </geometry>
    </collision>
  </link>
  <link name="finger-2-link">
    <inertial>
      <origin rpy="0.0 -1.2446030555722283e-60 -5.527147875260445e-76" xyz="0.008443385199673763 -0.03000000140815903 -1.2294397322420992e-09"/>
      <mass value="0.21288346600238772"/>
      <inertia ixx="7.903229595090933e-05" ixy="-1.5086702559845088e-33" ixz="-1.734723475976807e-18" iyy="1.9267709840120606e-05" iyz="-2.4009861057577842e-36" izz="6.796549349066469e-05"/>
    </inertial>
    <visual>
      <origin rpy="1.570796326794897 1.9230207024252956e-13 2.813099754978189e-29" xyz="0.04100000000000895 0.014999998591841007 -1.229445985018174e-09"/>
      <geometry>
        <mesh filename="package://cobot_description/meshes/left_finger-v1.stl" scale="0.001 0.001 0.001"/>
      </geometry>
    </visual>
    <collision>
      <origin rpy="1.570796326794897 1.9230207024252956e-13 2.813099754978189e-29" xyz="0.04100000000000895 0.014999998591841007 -1.229445985018174e-09"/>
      <geometry>
        <mesh filename="package://cobot_description/meshes/left_finger-v1.stl" scale="0.001 0.001 0.001"/>
      </geometry>
    </collision>
  </link>
  <joint name="finger-1-joint" type="prismatic">
    <origin rpy="-4.930380657631324e-32 -1.5707963267948966 0" xyz="0.0 0.015 0.040999999999999995"/>
    <parent link="gripper-base-link"/>
    <child link="finger-1-link"/>
    <axis xyz="1.0 2.524354896707238e-29 0.0"/>
    <limit effort="1000000" lower="-0.025" upper="0.0" velocity="1000000"/>
  </joint>
  <joint name="finger-2-joint" type="prismatic">
    <origin rpy="3.141592653589793 -1.5707963267948966 0" xyz="0.0 0.015 -0.040999999999999995"/>
    <parent link="gripper-base-link"/>
    <child link="finger-2-link"/>
    <axis xyz="1.0 -2.524354896707238e-29 0.0"/>
    <limit effort="1000000" lower="0.0" upper="0.025" velocity="1000000"/>
  </joint>
  <gazebo reference="finger-1-link">
    <material>Gazebo/SkyBlue</material>
  </gazebo>
  <gazebo reference="finger-2-link">
    <material>Gazebo/SkyBlue</material>
  </gazebo>
  <gazebo>
    <plugin filename="libgazebo_ros2_control.so" name="gazebo_ros2_control">
      <parameters>
                /home/salim/cobot_final_ws/install/cobot_control/share/cobot_control/config/cobat_controller.yaml
            </parameters>
    </plugin>
  </gazebo>
  <ros2_control name="GazeboSystem" type="system">
    <hardware>
      <plugin>gazebo_ros2_control/GazeboSystem</plugin>
    </hardware>
    <joint name="part-1-joint">
      <command_interface name="position"/>
      <state_interface name="position"/>
    </joint>
    <joint name="part-2-joint">
      <command_interface name="position"/>
      <state_interface name="position"/>
    </joint>
    <joint name="part-3-joint">
      <command_interface name="position"/>
      <state_interface name="position"/>
    </joint>
    <joint name="part-4-joint">
      <command_interface name="position"/>
      <state_interface name="position"/>
    </joint>
    <joint name="part-5-joint">
      <command_interface name="position"/>
      <state_interface name="position"/>
    </joint>
    <joint name="part-6-joint">
      <command_interface name="position"/>
      <state_interface name="position"/>
    </joint>
    <joint name="finger-1-joint">
      <command_interface name="position"/>
      <state_interface name="position"/>
    </joint>
    <joint name="finger-2-joint">
      <command_interface name="position"/>
      <state_interface name="position"/>
    </joint>
  </ros2_control>
</robot>
